<?xml version="1.0"?> 
<sdf version="1.4">
  <world name="default">
  <plugin name="model_push" filename="libsimple_world_plugin.so"/>
    <!-- Ground Plane -->
    <include>
      <uri>model://ground_plane</uri>
    </include>

    <include>
      <uri>model://sun</uri>
    </include>

      <model name="my_robot">
	<static>false</static>
        <link name='chassis'>
    	<inertial>
      	  <mass>10.0</mass>
          <inertia> <ixx>0.0416666666</ixx> 
	   	   <ixy>0.0</ixy> 
		   <ixz>0.0</ixz> 
		   <iyy>0.1416666666</iyy> 
		   <iyz>0.0</iyz>
		   <izz>0.1666666666</izz>
           </inertia>
        </inertial>
          <pose>0 0 .1 0 0 0</pose>
          <collision name='collision'>
            <geometry>
              <box>
                <size>.4 .2 .1</size>
              </box>
            </geometry>
          </collision>
          <visual name='visual'>
            <geometry>
              <box>
                <size>.4 .2 .1</size>
              </box>
            </geometry>
          </visual>
      </link>

       <link name='inv_pendulam'>
    	<inertial>
      	  <mass>1.0</mass>
          <inertia> <ixx>0.0133</ixx> 
	   	   <ixy>0.0</ixy> 
		   <ixz>0.0</ixz> 
		   <iyy>0.0133</iyy> 
		   <iyz>0.0</iyz>
		   <izz>0.00001</izz>
           </inertia>
        </inertial>
          <pose>0 0 .35 0 0 0</pose>
          <collision name='collision'>
            <geometry>
              <box>
                <size>.01 .01 .4</size>
              </box>
            </geometry>
          </collision>

          <visual name='visual'>
            <geometry>
              <box>
                <size>.01 .01 .4</size>
              </box>
            </geometry>
          </visual>
      </link>

      <link name="left_wheel">
  	<inertial>
      	  <mass>10.0</mass>
          <inertia> <ixx>0.02708333333</ixx> 
	   	   <ixy>0.0</ixy> 
		   <ixz>0.0</ixz> 
		   <iyy>0.02708333333</iyy> 
		   <iyz>0.0</iyz>
		   <izz>0.05</izz>
           </inertia>
        </inertial>
        <pose>0.2 0.13 0.1 0 1.5707 1.5707</pose>
        <collision name="collision">
          <geometry>
            <cylinder>
              <radius>.1</radius>
              <length>.05</length>
            </cylinder>
          </geometry>
        </collision>
        <visual name="visual">
          <geometry>
            <cylinder>
              <radius>.1</radius>
              <length>.05</length>
            </cylinder>
          </geometry>
        </visual>
      </link>

      <link name="left_wheel_2">
  	<inertial>
      	  <mass>10.0</mass>
          <inertia> <ixx>0.02708333333</ixx> 
	   	   <ixy>0.0</ixy> 
		   <ixz>0.0</ixz> 
		   <iyy>0.02708333333</iyy> 
		   <iyz>0.0</iyz>
		   <izz>0.05</izz>
           </inertia>
        </inertial>
        <pose>-0.2 0.13 0.1 0 1.5707 1.5707</pose>
        <collision name="collision">
          <geometry>
            <cylinder>
              <radius>.1</radius>
              <length>.05</length>
            </cylinder>
          </geometry>
        </collision>
        <visual name="visual">
          <geometry>
            <cylinder>
              <radius>.1</radius>
              <length>.05</length>
            </cylinder>
          </geometry>
        </visual>
      </link>

      <link name="right_wheel">
  	<inertial>
      	  <mass>10.0</mass>
          <inertia> <ixx>0.02708333333</ixx> 
	   	   <ixy>0.0</ixy> 
		   <ixz>0.0</ixz> 
		   <iyy>0.02708333333</iyy> 
		   <iyz>0.0</iyz>
		   <izz>0.05</izz>
           </inertia>
        </inertial>
        <pose>0.2 -0.13 0.1 0 1.5707 1.5707</pose>
        <collision name="collision">
          <geometry>
            <cylinder>
              <radius>.1</radius>
              <length>.05</length>
            </cylinder>
          </geometry>
        </collision>
        <visual name="visual">
          <geometry>
            <cylinder>
              <radius>.1</radius>
              <length>.05</length>
            </cylinder>
          </geometry>
        </visual>
      </link>

      <link name="right_wheel_2">
  	<inertial>
      	  <mass>10.0</mass>
          <inertia> <ixx>0.02708333333</ixx> 
	   	   <ixy>0.0</ixy> 
		   <ixz>0.0</ixz> 
		   <iyy>0.02708333333</iyy> 
		   <iyz>0.0</iyz>
		   <izz>0.05</izz>
           </inertia>
        </inertial>
        <pose>-0.2 -0.13 0.1 0 1.5707 1.5707</pose>
        <collision name="collision">
          <geometry>
            <cylinder>
              <radius>.1</radius>
              <length>.05</length>
            </cylinder>
          </geometry>
        </collision>
        <visual name="visual">
          <geometry>
            <cylinder>
              <radius>.1</radius>
              <length>.05</length>
            </cylinder>
          </geometry>
        </visual>
      </link>

      <joint type="revolute" name="pendulam_hinge">
	<pose>0 0 -0.2 0 0 0</pose>
        <child>inv_pendulam</child>
        <parent>chassis</parent>
        <axis>
          <xyz>0 1 0</xyz>
        </axis>
      </joint>

      <joint type="revolute" name="left_wheel_hinge">
        <child>left_wheel</child>
        <parent>chassis</parent>
        <axis>
          <xyz>0 1 0</xyz>
        </axis>
      </joint>

      <joint type="revolute" name="right_wheel_hinge">
        <child>right_wheel</child>
        <parent>chassis</parent>
        <axis>
          <xyz>0 1 0</xyz>
        </axis>
      </joint>

      <joint type="revolute" name="left_wheel_hinge_2">
        <child>left_wheel_2</child>
        <parent>chassis</parent>
        <axis>
          <xyz>0 1 0</xyz>
        </axis>
      </joint>

      <joint type="revolute" name="right_wheel_hinge_2">
        <child>right_wheel_2</child>
        <parent>chassis</parent>
        <axis>
          <xyz>0 1 0</xyz>
        </axis>
      </joint>
      <plugin name="model_measure" filename="libmodel_measure.so"/>
      </model>  
  </world>
</sdf>
